1712059488.2049127,dev,"2024-04-02 14:04:48,204",ERROR,"'AUTOSAR' object has no attribute 'find'"
Traceback (most recent call last):
  File "main.py", line 32, in main
  File "main.py", line 151, in mode_updater
  File "ecuc_partition_handling\ecuc_partition_parser.py", line 13, in __init__
AttributeError: 'AUTOSAR' object has no attribute 'find'
1712060817.251503,dev,"2024-04-02 14:26:57,251",ERROR,"'AUTOSAR' object has no attribute 'find'"
Traceback (most recent call last):
  File "main.py", line 32, in main
  File "main.py", line 151, in mode_updater
  File "ecuc_partition_handling\ecuc_partition_parser.py", line 13, in __init__
AttributeError: 'AUTOSAR' object has no attribute 'find'
1712060935.93908,dev,"2024-04-02 14:28:55,939",ERROR,"'AUTOSAR' object has no attribute 'find'"
Traceback (most recent call last):
  File "main.py", line 32, in main
  File "main.py", line 151, in mode_updater
  File "ecuc_partition_handling\ecuc_partition_parser.py", line 13, in __init__
AttributeError: 'AUTOSAR' object has no attribute 'find'
1712060950.5492084,dev,"2024-04-02 14:29:10,549",ERROR,"'AUTOSAR' object has no attribute 'find'"
Traceback (most recent call last):
  File "main.py", line 32, in main
  File "main.py", line 151, in mode_updater
  File "ecuc_partition_handling\ecuc_partition_parser.py", line 13, in __init__
AttributeError: 'AUTOSAR' object has no attribute 'find'
1712061389.0634592,dev,"2024-04-02 14:36:29,063",ERROR,"'AUTOSAR' object has no attribute 'find'"
Traceback (most recent call last):
  File "main.py", line 32, in main
  File "main.py", line 151, in mode_updater
  File "ecuc_partition_handling\ecuc_partition_parser.py", line 13, in __init__
AttributeError: 'AUTOSAR' object has no attribute 'find'
1712061456.7767813,dev,"2024-04-02 14:37:36,776",ERROR,"'AUTOSAR' object has no attribute 'find'"
Traceback (most recent call last):
  File "main.py", line 32, in main
  File "main.py", line 151, in mode_updater
  File "ecuc_partition_handling\ecuc_partition_parser.py", line 13, in __init__
AttributeError: 'AUTOSAR' object has no attribute 'find'
1712061546.8081226,dev,"2024-04-02 14:39:06,808",ERROR,"'AUTOSAR' object has no attribute 'find'"
Traceback (most recent call last):
  File "main.py", line 32, in main
  File "main.py", line 151, in mode_updater
  File "ecuc_partition_handling\ecuc_partition_parser.py", line 13, in __init__
AttributeError: 'AUTOSAR' object has no attribute 'find'
1712061644.235772,dev,"2024-04-02 14:40:44,235",ERROR,"'AUTOSAR' object has no attribute 'find'"
Traceback (most recent call last):
  File "main.py", line 32, in main
  File "main.py", line 151, in mode_updater
  File "ecuc_partition_handling\ecuc_partition_parser.py", line 13, in __init__
AttributeError: 'AUTOSAR' object has no attribute 'find'
1712061654.2264614,dev,"2024-04-02 14:40:54,226",ERROR,"'AUTOSAR' object has no attribute 'find'"
Traceback (most recent call last):
  File "main.py", line 32, in main
  File "main.py", line 151, in mode_updater
  File "ecuc_partition_handling\ecuc_partition_parser.py", line 13, in __init__
AttributeError: 'AUTOSAR' object has no attribute 'find'
1712068392.4171124,dev,"2024-04-02 16:33:12,417",ERROR,"'AUTOSAR' object has no attribute 'find'"
Traceback (most recent call last):
  File "main.py", line 32, in main
  File "main.py", line 151, in mode_updater
  File "ecuc_partition_handling\ecuc_partition_parser.py", line 13, in __init__
AttributeError: 'AUTOSAR' object has no attribute 'find'
1712642144.6652849,dev,"2024-04-09 07:55:44,665",ERROR,"list index out of range"
Traceback (most recent call last):
  File "main.py", line 33, in main
  File "main.py", line 155, in mode_updater
IndexError: list index out of range
1713173303.7551458,dev,"2024-04-15 11:28:23,755",ERROR,".\in\InitExport does not exist. Please check value given."
Traceback (most recent call last):
  File "main.py", line 40, in main
  File "main.py", line 116, in mode_updater
  File "confmanager_modes\confmanager_updater.py", line 16, in __init__
  File "utils\filehandling.py", line 32, in check_if_folder_exists
ValueError: .\in\InitExport does not exist. Please check value given.
1713174550.354175,dev,"2024-04-15 11:49:10,354",ERROR,"'EcucPartition_OsApp_C'"
Traceback (most recent call last):
  File "main.py", line 35, in main
  File "main.py", line 61, in ecuc_partiton_updater
  File "ecuc_partition_handling\ecuc_partition_updater.py", line 61, in port_delta
  File "ecuc_partition_handling\ecuc_partition_parser.py", line 114, in update_ecuc_iref
KeyError: 'EcucPartition_OsApp_C'
1713176534.224381,dev,"2024-04-15 12:22:14,224",ERROR,"'EcucPartition_OsApp_C'"
Traceback (most recent call last):
  File "main.py", line 35, in main
  File "main.py", line 61, in ecuc_partiton_updater
  File "ecuc_partition_handling\ecuc_partition_updater.py", line 51, in port_delta
  File "ecuc_partition_handling\ecuc_partition_parser.py", line 114, in update_ecuc_iref
KeyError: 'EcucPartition_OsApp_C'
